ERROR 2019-09-06 18:22:32,605 functions 11571 123145312813056 page1
ERROR 2019-09-06 18:22:38,553 functions 11571 123145312813056 requesting 5.948101043701172
ERROR 2019-09-06 18:22:38,967 functions 11571 123145312813056 sub-requests 0.023607254028320312
ERROR 2019-09-06 18:22:38,967 functions 11571 123145312813056 page2
ERROR 2019-09-06 18:22:39,336 functions 11571 123145312813056 requesting 0.36857104301452637
ERROR 2019-09-06 18:22:41,163 functions 11571 123145312813056 dict 1.5652210712432861
ERROR 2019-09-06 18:22:41,235 forms 11571 123145312813056 total 8.630343914031982
ERROR 2019-09-06 18:24:30,154 functions 11571 123145312813056 page1
ERROR 2019-09-06 18:24:36,335 functions 11571 123145312813056 requesting 6.181041955947876
ERROR 2019-09-06 18:24:37,280 functions 11571 123145312813056 sub-requests 0.11923909187316895
ERROR 2019-09-06 18:24:37,280 functions 11571 123145312813056 page2
ERROR 2019-09-06 18:24:40,547 functions 11571 123145312813056 requesting 3.2661430835723877
ERROR 2019-09-06 18:24:49,253 functions 11571 123145312813056 dict 8.457561254501343
ERROR 2019-09-06 18:24:49,655 forms 11571 123145312813056 total 19.502142906188965
ERROR 2019-09-08 21:24:31,509 log 25999 123145312813056 Internal Server Error: /
Traceback (most recent call last):
  File "/Users/christopherencalada/Desktop/Scraping project/venv/lib/python3.7/site-packages/django/core/handlers/exception.py", line 34, in inner
    response = get_response(request)
  File "/Users/christopherencalada/Desktop/Scraping project/venv/lib/python3.7/site-packages/django/core/handlers/base.py", line 115, in _get_response
    response = self.process_exception_by_middleware(e, request)
  File "/Users/christopherencalada/Desktop/Scraping project/venv/lib/python3.7/site-packages/django/core/handlers/base.py", line 113, in _get_response
    response = wrapped_callback(request, *callback_args, **callback_kwargs)
  File "/Users/christopherencalada/Desktop/Scraping project/scrape_libgen/b_books/downloads/forms.py", line 40, in Author
    if Books.objects.get(Author__contains=cd).exists():
  File "/Users/christopherencalada/Desktop/Scraping project/venv/lib/python3.7/site-packages/django/db/models/manager.py", line 82, in manager_method
    return getattr(self.get_queryset(), name)(*args, **kwargs)
  File "/Users/christopherencalada/Desktop/Scraping project/venv/lib/python3.7/site-packages/django/db/models/query.py", line 412, in get
    (self.model._meta.object_name, num)
downloads.models.Books.MultipleObjectsReturned: get() returned more than one Books -- it returned 166!
ERROR 2019-09-08 21:27:12,651 functions 26022 123145312813056 page1
ERROR 2019-09-08 21:27:19,156 functions 26022 123145312813056 requesting 6.504235744476318
ERROR 2019-09-08 21:27:20,288 functions 26022 123145312813056 sub-requests 0.14404082298278809
ERROR 2019-09-08 21:27:20,288 functions 26022 123145312813056 page2
ERROR 2019-09-08 21:27:20,936 functions 26022 123145312813056 requesting 0.6474399566650391
ERROR 2019-09-08 21:27:21,754 functions 26022 123145312813056 sub-requests 0.08769702911376953
ERROR 2019-09-08 21:27:21,755 functions 26022 123145312813056 page3
ERROR 2019-09-08 21:27:22,177 functions 26022 123145312813056 requesting 0.4216318130493164
ERROR 2019-09-08 21:27:53,790 functions 26022 123145312813056 dict 31.347049951553345
ERROR 2019-09-08 21:27:54,613 forms 26022 123145312813056 total 42.02308893203735
ERROR 2019-09-08 21:30:04,488 forms 26038 123145312813056 total 0.007861852645874023
ERROR 2019-09-09 17:51:30,716 log 27365 123145312813056 Internal Server Error: /
Traceback (most recent call last):
  File "/Users/christopherencalada/Desktop/Scraping project/venv/lib/python3.7/site-packages/django/core/handlers/exception.py", line 34, in inner
    response = get_response(request)
  File "/Users/christopherencalada/Desktop/Scraping project/venv/lib/python3.7/site-packages/django/core/handlers/base.py", line 115, in _get_response
    response = self.process_exception_by_middleware(e, request)
  File "/Users/christopherencalada/Desktop/Scraping project/venv/lib/python3.7/site-packages/django/core/handlers/base.py", line 113, in _get_response
    response = wrapped_callback(request, *callback_args, **callback_kwargs)
  File "/Users/christopherencalada/Desktop/Scraping project/scrape_libgen/b_books/downloads/forms.py", line 45, in Author
    return redirect('Author',A_Name=cd)
  File "/Users/christopherencalada/Desktop/Scraping project/venv/lib/python3.7/site-packages/django/shortcuts.py", line 58, in redirect
    return redirect_class(resolve_url(to, *args, **kwargs))
  File "/Users/christopherencalada/Desktop/Scraping project/venv/lib/python3.7/site-packages/django/shortcuts.py", line 148, in resolve_url
    return reverse(to, args=args, kwargs=kwargs)
  File "/Users/christopherencalada/Desktop/Scraping project/venv/lib/python3.7/site-packages/django/urls/base.py", line 90, in reverse
    return iri_to_uri(resolver._reverse_with_prefix(view, prefix, *args, **kwargs))
  File "/Users/christopherencalada/Desktop/Scraping project/venv/lib/python3.7/site-packages/django/urls/resolvers.py", line 668, in _reverse_with_prefix
    raise NoReverseMatch(msg)
django.urls.exceptions.NoReverseMatch: Reverse for 'Author' with keyword arguments '{'A_Name': 'haruki murakami'}' not found. 1 pattern(s) tried: ['authors/(?P<A_name>[^/]+)/$']
ERROR 2019-09-09 17:56:42,193 log 27375 123145312813056 Internal Server Error: /
Traceback (most recent call last):
  File "/Users/christopherencalada/Desktop/Scraping project/venv/lib/python3.7/site-packages/django/core/handlers/exception.py", line 34, in inner
    response = get_response(request)
  File "/Users/christopherencalada/Desktop/Scraping project/venv/lib/python3.7/site-packages/django/core/handlers/base.py", line 115, in _get_response
    response = self.process_exception_by_middleware(e, request)
  File "/Users/christopherencalada/Desktop/Scraping project/venv/lib/python3.7/site-packages/django/core/handlers/base.py", line 113, in _get_response
    response = wrapped_callback(request, *callback_args, **callback_kwargs)
  File "/Users/christopherencalada/Desktop/Scraping project/scrape_libgen/b_books/downloads/forms.py", line 45, in Author
    return redirect('Author',A_Name=cd)
  File "/Users/christopherencalada/Desktop/Scraping project/venv/lib/python3.7/site-packages/django/shortcuts.py", line 58, in redirect
    return redirect_class(resolve_url(to, *args, **kwargs))
  File "/Users/christopherencalada/Desktop/Scraping project/venv/lib/python3.7/site-packages/django/shortcuts.py", line 148, in resolve_url
    return reverse(to, args=args, kwargs=kwargs)
  File "/Users/christopherencalada/Desktop/Scraping project/venv/lib/python3.7/site-packages/django/urls/base.py", line 90, in reverse
    return iri_to_uri(resolver._reverse_with_prefix(view, prefix, *args, **kwargs))
  File "/Users/christopherencalada/Desktop/Scraping project/venv/lib/python3.7/site-packages/django/urls/resolvers.py", line 668, in _reverse_with_prefix
    raise NoReverseMatch(msg)
django.urls.exceptions.NoReverseMatch: Reverse for 'Author' with keyword arguments '{'A_Name': 'murakami'}' not found. 1 pattern(s) tried: ['authors/(?P<A_name>[^/]+)/$']
ERROR 2019-09-09 17:58:18,384 log 27375 123145312813056 Internal Server Error: /
Traceback (most recent call last):
  File "/Users/christopherencalada/Desktop/Scraping project/venv/lib/python3.7/site-packages/django/core/handlers/exception.py", line 34, in inner
    response = get_response(request)
  File "/Users/christopherencalada/Desktop/Scraping project/venv/lib/python3.7/site-packages/django/core/handlers/base.py", line 115, in _get_response
    response = self.process_exception_by_middleware(e, request)
  File "/Users/christopherencalada/Desktop/Scraping project/venv/lib/python3.7/site-packages/django/core/handlers/base.py", line 113, in _get_response
    response = wrapped_callback(request, *callback_args, **callback_kwargs)
  File "/Users/christopherencalada/Desktop/Scraping project/scrape_libgen/b_books/downloads/forms.py", line 45, in Author
    return redirect('Author',A_Name=cd)
  File "/Users/christopherencalada/Desktop/Scraping project/venv/lib/python3.7/site-packages/django/shortcuts.py", line 58, in redirect
    return redirect_class(resolve_url(to, *args, **kwargs))
  File "/Users/christopherencalada/Desktop/Scraping project/venv/lib/python3.7/site-packages/django/shortcuts.py", line 148, in resolve_url
    return reverse(to, args=args, kwargs=kwargs)
  File "/Users/christopherencalada/Desktop/Scraping project/venv/lib/python3.7/site-packages/django/urls/base.py", line 90, in reverse
    return iri_to_uri(resolver._reverse_with_prefix(view, prefix, *args, **kwargs))
  File "/Users/christopherencalada/Desktop/Scraping project/venv/lib/python3.7/site-packages/django/urls/resolvers.py", line 668, in _reverse_with_prefix
    raise NoReverseMatch(msg)
django.urls.exceptions.NoReverseMatch: Reverse for 'Author' with keyword arguments '{'A_Name': 'murakami'}' not found. 1 pattern(s) tried: ['authors/(?P<A_name>[^/]+)/$']
ERROR 2019-09-09 18:42:05,772 log 27429 123145312813056 Internal Server Error: /
Traceback (most recent call last):
  File "/Users/christopherencalada/Desktop/Scraping project/venv/lib/python3.7/site-packages/django/core/handlers/exception.py", line 34, in inner
    response = get_response(request)
  File "/Users/christopherencalada/Desktop/Scraping project/venv/lib/python3.7/site-packages/django/core/handlers/base.py", line 115, in _get_response
    response = self.process_exception_by_middleware(e, request)
  File "/Users/christopherencalada/Desktop/Scraping project/venv/lib/python3.7/site-packages/django/core/handlers/base.py", line 113, in _get_response
    response = wrapped_callback(request, *callback_args, **callback_kwargs)
  File "/Users/christopherencalada/Desktop/Scraping project/scrape_libgen/b_books/downloads/forms.py", line 45, in Author
    return redirect(reverse('Author',A_Name=cd))
NameError: name 'reverse' is not defined
ERROR 2019-09-09 18:43:00,299 log 27440 123145312813056 Internal Server Error: /
Traceback (most recent call last):
  File "/Users/christopherencalada/Desktop/Scraping project/venv/lib/python3.7/site-packages/django/core/handlers/exception.py", line 34, in inner
    response = get_response(request)
  File "/Users/christopherencalada/Desktop/Scraping project/venv/lib/python3.7/site-packages/django/core/handlers/base.py", line 115, in _get_response
    response = self.process_exception_by_middleware(e, request)
  File "/Users/christopherencalada/Desktop/Scraping project/venv/lib/python3.7/site-packages/django/core/handlers/base.py", line 113, in _get_response
    response = wrapped_callback(request, *callback_args, **callback_kwargs)
  File "/Users/christopherencalada/Desktop/Scraping project/scrape_libgen/b_books/downloads/forms.py", line 46, in Author
    return redirect(reverse('Author',A_Name=cd))
TypeError: reverse() got an unexpected keyword argument 'A_Name'
ERROR 2019-09-09 18:43:54,011 log 27445 123145312813056 Internal Server Error: /authors/murakami/
Traceback (most recent call last):
  File "/Users/christopherencalada/Desktop/Scraping project/venv/lib/python3.7/site-packages/django/core/handlers/exception.py", line 34, in inner
    response = get_response(request)
  File "/Users/christopherencalada/Desktop/Scraping project/venv/lib/python3.7/site-packages/django/core/handlers/base.py", line 115, in _get_response
    response = self.process_exception_by_middleware(e, request)
  File "/Users/christopherencalada/Desktop/Scraping project/venv/lib/python3.7/site-packages/django/core/handlers/base.py", line 113, in _get_response
    response = wrapped_callback(request, *callback_args, **callback_kwargs)
TypeError: Author_specific() got an unexpected keyword argument 'A_name'
ERROR 2019-09-09 18:48:02,079 log 27450 123145312813056 Internal Server Error: /
Traceback (most recent call last):
  File "/Users/christopherencalada/Desktop/Scraping project/venv/lib/python3.7/site-packages/django/core/handlers/exception.py", line 34, in inner
    response = get_response(request)
  File "/Users/christopherencalada/Desktop/Scraping project/venv/lib/python3.7/site-packages/django/core/handlers/base.py", line 115, in _get_response
    response = self.process_exception_by_middleware(e, request)
  File "/Users/christopherencalada/Desktop/Scraping project/venv/lib/python3.7/site-packages/django/core/handlers/base.py", line 113, in _get_response
    response = wrapped_callback(request, *callback_args, **callback_kwargs)
  File "/Users/christopherencalada/Desktop/Scraping project/scrape_libgen/b_books/downloads/forms.py", line 46, in Author
    return redirect(reverse('Author',args=[A_Name]))
NameError: name 'A_Name' is not defined
ERROR 2019-09-09 18:49:17,020 log 27453 123145312813056 Internal Server Error: /
Traceback (most recent call last):
  File "/Users/christopherencalada/Desktop/Scraping project/venv/lib/python3.7/site-packages/django/core/handlers/exception.py", line 34, in inner
    response = get_response(request)
  File "/Users/christopherencalada/Desktop/Scraping project/venv/lib/python3.7/site-packages/django/core/handlers/base.py", line 115, in _get_response
    response = self.process_exception_by_middleware(e, request)
  File "/Users/christopherencalada/Desktop/Scraping project/venv/lib/python3.7/site-packages/django/core/handlers/base.py", line 113, in _get_response
    response = wrapped_callback(request, *callback_args, **callback_kwargs)
  File "/Users/christopherencalada/Desktop/Scraping project/scrape_libgen/b_books/downloads/forms.py", line 46, in Author
    return redirect(reverse('A:Author',args=[A_Name]))
NameError: name 'A_Name' is not defined
ERROR 2019-09-09 18:50:09,919 log 27457 123145312813056 Internal Server Error: /
Traceback (most recent call last):
  File "/Users/christopherencalada/Desktop/Scraping project/venv/lib/python3.7/site-packages/django/urls/base.py", line 75, in reverse
    extra, resolver = resolver.namespace_dict[ns]
KeyError: 'A'

During handling of the above exception, another exception occurred:

Traceback (most recent call last):
  File "/Users/christopherencalada/Desktop/Scraping project/venv/lib/python3.7/site-packages/django/core/handlers/exception.py", line 34, in inner
    response = get_response(request)
  File "/Users/christopherencalada/Desktop/Scraping project/venv/lib/python3.7/site-packages/django/core/handlers/base.py", line 115, in _get_response
    response = self.process_exception_by_middleware(e, request)
  File "/Users/christopherencalada/Desktop/Scraping project/venv/lib/python3.7/site-packages/django/core/handlers/base.py", line 113, in _get_response
    response = wrapped_callback(request, *callback_args, **callback_kwargs)
  File "/Users/christopherencalada/Desktop/Scraping project/scrape_libgen/b_books/downloads/forms.py", line 47, in Author
    return redirect(reverse('A:Author',args=[name]))
  File "/Users/christopherencalada/Desktop/Scraping project/venv/lib/python3.7/site-packages/django/urls/base.py", line 86, in reverse
    raise NoReverseMatch("%s is not a registered namespace" % key)
django.urls.exceptions.NoReverseMatch: 'A' is not a registered namespace
ERROR 2019-09-09 18:51:31,016 log 27466 123145312813056 Internal Server Error: /
Traceback (most recent call last):
  File "/Users/christopherencalada/Desktop/Scraping project/venv/lib/python3.7/site-packages/django/urls/base.py", line 75, in reverse
    extra, resolver = resolver.namespace_dict[ns]
KeyError: 'A'

During handling of the above exception, another exception occurred:

Traceback (most recent call last):
  File "/Users/christopherencalada/Desktop/Scraping project/venv/lib/python3.7/site-packages/django/core/handlers/exception.py", line 34, in inner
    response = get_response(request)
  File "/Users/christopherencalada/Desktop/Scraping project/venv/lib/python3.7/site-packages/django/core/handlers/base.py", line 115, in _get_response
    response = self.process_exception_by_middleware(e, request)
  File "/Users/christopherencalada/Desktop/Scraping project/venv/lib/python3.7/site-packages/django/core/handlers/base.py", line 113, in _get_response
    response = wrapped_callback(request, *callback_args, **callback_kwargs)
  File "/Users/christopherencalada/Desktop/Scraping project/scrape_libgen/b_books/downloads/forms.py", line 47, in Author
    return redirect(reverse('A:Author',args=[name]))
  File "/Users/christopherencalada/Desktop/Scraping project/venv/lib/python3.7/site-packages/django/urls/base.py", line 86, in reverse
    raise NoReverseMatch("%s is not a registered namespace" % key)
django.urls.exceptions.NoReverseMatch: 'A' is not a registered namespace
ERROR 2019-09-09 18:51:44,001 log 27471 123145312813056 Internal Server Error: /murakami/
Traceback (most recent call last):
  File "/Users/christopherencalada/Desktop/Scraping project/venv/lib/python3.7/site-packages/django/core/handlers/exception.py", line 34, in inner
    response = get_response(request)
  File "/Users/christopherencalada/Desktop/Scraping project/venv/lib/python3.7/site-packages/django/core/handlers/base.py", line 115, in _get_response
    response = self.process_exception_by_middleware(e, request)
  File "/Users/christopherencalada/Desktop/Scraping project/venv/lib/python3.7/site-packages/django/core/handlers/base.py", line 113, in _get_response
    response = wrapped_callback(request, *callback_args, **callback_kwargs)
TypeError: Author_specific() got an unexpected keyword argument 'name'
ERROR 2019-09-09 18:52:48,280 log 27476 123145312813056 Internal Server Error: /murakami/
Traceback (most recent call last):
  File "/Users/christopherencalada/Desktop/Scraping project/venv/lib/python3.7/site-packages/django/core/handlers/exception.py", line 34, in inner
    response = get_response(request)
  File "/Users/christopherencalada/Desktop/Scraping project/venv/lib/python3.7/site-packages/django/core/handlers/base.py", line 115, in _get_response
    response = self.process_exception_by_middleware(e, request)
  File "/Users/christopherencalada/Desktop/Scraping project/venv/lib/python3.7/site-packages/django/core/handlers/base.py", line 113, in _get_response
    response = wrapped_callback(request, *callback_args, **callback_kwargs)
TypeError: Author_specific() got an unexpected keyword argument 'name'
ERROR 2019-09-09 18:53:15,860 log 27478 123145312813056 Internal Server Error: /
Traceback (most recent call last):
  File "/Users/christopherencalada/Desktop/Scraping project/venv/lib/python3.7/site-packages/django/core/handlers/exception.py", line 34, in inner
    response = get_response(request)
  File "/Users/christopherencalada/Desktop/Scraping project/venv/lib/python3.7/site-packages/django/core/handlers/base.py", line 115, in _get_response
    response = self.process_exception_by_middleware(e, request)
  File "/Users/christopherencalada/Desktop/Scraping project/venv/lib/python3.7/site-packages/django/core/handlers/base.py", line 113, in _get_response
    response = wrapped_callback(request, *callback_args, **callback_kwargs)
  File "/Users/christopherencalada/Desktop/Scraping project/scrape_libgen/b_books/downloads/forms.py", line 47, in Author
    return redirect(reverse('Author'))
  File "/Users/christopherencalada/Desktop/Scraping project/venv/lib/python3.7/site-packages/django/urls/base.py", line 90, in reverse
    return iri_to_uri(resolver._reverse_with_prefix(view, prefix, *args, **kwargs))
  File "/Users/christopherencalada/Desktop/Scraping project/venv/lib/python3.7/site-packages/django/urls/resolvers.py", line 668, in _reverse_with_prefix
    raise NoReverseMatch(msg)
django.urls.exceptions.NoReverseMatch: Reverse for 'Author' with no arguments not found. 1 pattern(s) tried: ['(?P<name>[^/]+)/$']
ERROR 2019-09-09 21:13:15,766 log 27630 123145312813056 Internal Server Error: /
Traceback (most recent call last):
  File "/Users/christopherencalada/Desktop/Scraping project/venv/lib/python3.7/site-packages/django/core/handlers/exception.py", line 34, in inner
    response = get_response(request)
  File "/Users/christopherencalada/Desktop/Scraping project/venv/lib/python3.7/site-packages/django/core/handlers/base.py", line 115, in _get_response
    response = self.process_exception_by_middleware(e, request)
  File "/Users/christopherencalada/Desktop/Scraping project/venv/lib/python3.7/site-packages/django/core/handlers/base.py", line 113, in _get_response
    response = wrapped_callback(request, *callback_args, **callback_kwargs)
  File "/Users/christopherencalada/Desktop/Scraping project/scrape_libgen/b_books/downloads/forms.py", line 47, in Author
    return redirect(Author_redirect)
NameError: name 'Author_redirect' is not defined
ERROR 2019-09-09 21:13:57,688 log 27634 123145312813056 Internal Server Error: /
Traceback (most recent call last):
  File "/Users/christopherencalada/Desktop/Scraping project/venv/lib/python3.7/site-packages/django/core/handlers/exception.py", line 34, in inner
    response = get_response(request)
  File "/Users/christopherencalada/Desktop/Scraping project/venv/lib/python3.7/site-packages/django/core/handlers/base.py", line 115, in _get_response
    response = self.process_exception_by_middleware(e, request)
  File "/Users/christopherencalada/Desktop/Scraping project/venv/lib/python3.7/site-packages/django/core/handlers/base.py", line 113, in _get_response
    response = wrapped_callback(request, *callback_args, **callback_kwargs)
  File "/Users/christopherencalada/Desktop/Scraping project/scrape_libgen/b_books/downloads/forms.py", line 47, in Author
    return redirect(Author_redirect)
NameError: name 'Author_redirect' is not defined
ERROR 2019-09-09 21:14:23,779 log 27637 123145312813056 Internal Server Error: /
Traceback (most recent call last):
  File "/Users/christopherencalada/Desktop/Scraping project/venv/lib/python3.7/site-packages/django/core/handlers/exception.py", line 34, in inner
    response = get_response(request)
  File "/Users/christopherencalada/Desktop/Scraping project/venv/lib/python3.7/site-packages/django/core/handlers/base.py", line 115, in _get_response
    response = self.process_exception_by_middleware(e, request)
  File "/Users/christopherencalada/Desktop/Scraping project/venv/lib/python3.7/site-packages/django/core/handlers/base.py", line 113, in _get_response
    response = wrapped_callback(request, *callback_args, **callback_kwargs)
  File "/Users/christopherencalada/Desktop/Scraping project/scrape_libgen/b_books/downloads/forms.py", line 46, in Author
    return redirect(Author_redirect)
NameError: name 'Author_redirect' is not defined
ERROR 2019-09-09 21:15:12,394 log 27647 123145312813056 Internal Server Error: /
Traceback (most recent call last):
  File "/Users/christopherencalada/Desktop/Scraping project/venv/lib/python3.7/site-packages/django/core/handlers/exception.py", line 34, in inner
    response = get_response(request)
  File "/Users/christopherencalada/Desktop/Scraping project/venv/lib/python3.7/site-packages/django/core/handlers/base.py", line 115, in _get_response
    response = self.process_exception_by_middleware(e, request)
  File "/Users/christopherencalada/Desktop/Scraping project/venv/lib/python3.7/site-packages/django/core/handlers/base.py", line 113, in _get_response
    response = wrapped_callback(request, *callback_args, **callback_kwargs)
  File "/Users/christopherencalada/Desktop/Scraping project/scrape_libgen/b_books/downloads/forms.py", line 46, in Author
    return redirect(Author_redirect)
NameError: name 'Author_redirect' is not defined
ERROR 2019-09-09 21:17:09,916 log 27659 123145312813056 Internal Server Error: /
Traceback (most recent call last):
  File "/Users/christopherencalada/Desktop/Scraping project/venv/lib/python3.7/site-packages/django/core/handlers/exception.py", line 34, in inner
    response = get_response(request)
  File "/Users/christopherencalada/Desktop/Scraping project/venv/lib/python3.7/site-packages/django/core/handlers/base.py", line 115, in _get_response
    response = self.process_exception_by_middleware(e, request)
  File "/Users/christopherencalada/Desktop/Scraping project/venv/lib/python3.7/site-packages/django/core/handlers/base.py", line 113, in _get_response
    response = wrapped_callback(request, *callback_args, **callback_kwargs)
  File "/Users/christopherencalada/Desktop/Scraping project/scrape_libgen/b_books/downloads/forms.py", line 45, in Author
    logger.debug(reverse('Author/'))
  File "/Users/christopherencalada/Desktop/Scraping project/venv/lib/python3.7/site-packages/django/urls/base.py", line 90, in reverse
    return iri_to_uri(resolver._reverse_with_prefix(view, prefix, *args, **kwargs))
  File "/Users/christopherencalada/Desktop/Scraping project/venv/lib/python3.7/site-packages/django/urls/resolvers.py", line 668, in _reverse_with_prefix
    raise NoReverseMatch(msg)
django.urls.exceptions.NoReverseMatch: Reverse for 'Author/' not found. 'Author/' is not a valid view function or pattern name.
ERROR 2019-09-09 22:53:11,036 log 27920 123145312813056 Internal Server Error: /
Traceback (most recent call last):
  File "/Users/christopherencalada/Desktop/Scraping project/venv/lib/python3.7/site-packages/django/core/handlers/exception.py", line 34, in inner
    response = get_response(request)
  File "/Users/christopherencalada/Desktop/Scraping project/venv/lib/python3.7/site-packages/django/core/handlers/base.py", line 115, in _get_response
    response = self.process_exception_by_middleware(e, request)
  File "/Users/christopherencalada/Desktop/Scraping project/venv/lib/python3.7/site-packages/django/core/handlers/base.py", line 113, in _get_response
    response = wrapped_callback(request, *callback_args, **callback_kwargs)
  File "/Users/christopherencalada/Desktop/Scraping project/scrape_libgen/b_books/downloads/forms.py", line 45, in Author
    logger.debug(reverse('Author'))
  File "/Users/christopherencalada/Desktop/Scraping project/venv/lib/python3.7/site-packages/django/urls/base.py", line 90, in reverse
    return iri_to_uri(resolver._reverse_with_prefix(view, prefix, *args, **kwargs))
  File "/Users/christopherencalada/Desktop/Scraping project/venv/lib/python3.7/site-packages/django/urls/resolvers.py", line 668, in _reverse_with_prefix
    raise NoReverseMatch(msg)
django.urls.exceptions.NoReverseMatch: Reverse for 'Author' with no arguments not found. 1 pattern(s) tried: ['Author/(?P<name>[^/]+)/$']
ERROR 2019-09-09 22:53:35,886 log 27923 123145312813056 Internal Server Error: /
Traceback (most recent call last):
  File "/Users/christopherencalada/Desktop/Scraping project/venv/lib/python3.7/site-packages/django/core/handlers/exception.py", line 34, in inner
    response = get_response(request)
  File "/Users/christopherencalada/Desktop/Scraping project/venv/lib/python3.7/site-packages/django/core/handlers/base.py", line 115, in _get_response
    response = self.process_exception_by_middleware(e, request)
  File "/Users/christopherencalada/Desktop/Scraping project/venv/lib/python3.7/site-packages/django/core/handlers/base.py", line 113, in _get_response
    response = wrapped_callback(request, *callback_args, **callback_kwargs)
  File "/Users/christopherencalada/Desktop/Scraping project/scrape_libgen/b_books/downloads/forms.py", line 45, in Author
    logger.debug(reverse('Author'))
  File "/Users/christopherencalada/Desktop/Scraping project/venv/lib/python3.7/site-packages/django/urls/base.py", line 90, in reverse
    return iri_to_uri(resolver._reverse_with_prefix(view, prefix, *args, **kwargs))
  File "/Users/christopherencalada/Desktop/Scraping project/venv/lib/python3.7/site-packages/django/urls/resolvers.py", line 668, in _reverse_with_prefix
    raise NoReverseMatch(msg)
django.urls.exceptions.NoReverseMatch: Reverse for 'Author' with no arguments not found. 1 pattern(s) tried: ['Author/(?P<name>[^/]+)/$']
ERROR 2019-09-09 22:53:54,576 log 27926 123145312813056 Internal Server Error: /
Traceback (most recent call last):
  File "/Users/christopherencalada/Desktop/Scraping project/venv/lib/python3.7/site-packages/django/core/handlers/exception.py", line 34, in inner
    response = get_response(request)
  File "/Users/christopherencalada/Desktop/Scraping project/venv/lib/python3.7/site-packages/django/core/handlers/base.py", line 115, in _get_response
    response = self.process_exception_by_middleware(e, request)
  File "/Users/christopherencalada/Desktop/Scraping project/venv/lib/python3.7/site-packages/django/core/handlers/base.py", line 113, in _get_response
    response = wrapped_callback(request, *callback_args, **callback_kwargs)
  File "/Users/christopherencalada/Desktop/Scraping project/scrape_libgen/b_books/downloads/forms.py", line 45, in Author
    logger.debug(reverse('Author',name=cd))
TypeError: reverse() got an unexpected keyword argument 'name'
ERROR 2019-09-09 22:57:42,700 log 27938 123145312813056 Internal Server Error: /
Traceback (most recent call last):
  File "/Users/christopherencalada/Desktop/Scraping project/venv/lib/python3.7/site-packages/django/core/handlers/exception.py", line 34, in inner
    response = get_response(request)
  File "/Users/christopherencalada/Desktop/Scraping project/venv/lib/python3.7/site-packages/django/core/handlers/base.py", line 115, in _get_response
    response = self.process_exception_by_middleware(e, request)
  File "/Users/christopherencalada/Desktop/Scraping project/venv/lib/python3.7/site-packages/django/core/handlers/base.py", line 113, in _get_response
    response = wrapped_callback(request, *callback_args, **callback_kwargs)
  File "/Users/christopherencalada/Desktop/Scraping project/scrape_libgen/b_books/downloads/forms.py", line 45, in Author
    logger.debug(reverse('Author'))
  File "/Users/christopherencalada/Desktop/Scraping project/venv/lib/python3.7/site-packages/django/urls/base.py", line 90, in reverse
    return iri_to_uri(resolver._reverse_with_prefix(view, prefix, *args, **kwargs))
  File "/Users/christopherencalada/Desktop/Scraping project/venv/lib/python3.7/site-packages/django/urls/resolvers.py", line 668, in _reverse_with_prefix
    raise NoReverseMatch(msg)
django.urls.exceptions.NoReverseMatch: Reverse for 'Author' with no arguments not found. 1 pattern(s) tried: ['Author/(?P<name>[^/]+)/$']
ERROR 2019-09-09 22:58:11,459 log 27941 123145312813056 Internal Server Error: /
Traceback (most recent call last):
  File "/Users/christopherencalada/Desktop/Scraping project/venv/lib/python3.7/site-packages/django/core/handlers/exception.py", line 34, in inner
    response = get_response(request)
  File "/Users/christopherencalada/Desktop/Scraping project/venv/lib/python3.7/site-packages/django/core/handlers/base.py", line 115, in _get_response
    response = self.process_exception_by_middleware(e, request)
  File "/Users/christopherencalada/Desktop/Scraping project/venv/lib/python3.7/site-packages/django/core/handlers/base.py", line 113, in _get_response
    response = wrapped_callback(request, *callback_args, **callback_kwargs)
  File "/Users/christopherencalada/Desktop/Scraping project/scrape_libgen/b_books/downloads/forms.py", line 45, in Author
    return redirect(reverse('Author'),args=cd)
  File "/Users/christopherencalada/Desktop/Scraping project/venv/lib/python3.7/site-packages/django/urls/base.py", line 90, in reverse
    return iri_to_uri(resolver._reverse_with_prefix(view, prefix, *args, **kwargs))
  File "/Users/christopherencalada/Desktop/Scraping project/venv/lib/python3.7/site-packages/django/urls/resolvers.py", line 668, in _reverse_with_prefix
    raise NoReverseMatch(msg)
django.urls.exceptions.NoReverseMatch: Reverse for 'Author' with no arguments not found. 1 pattern(s) tried: ['Author/(?P<name>[^/]+)/$']
ERROR 2019-09-09 22:58:59,105 log 27949 123145312813056 Internal Server Error: /
Traceback (most recent call last):
  File "/Users/christopherencalada/Desktop/Scraping project/venv/lib/python3.7/site-packages/django/core/handlers/exception.py", line 34, in inner
    response = get_response(request)
  File "/Users/christopherencalada/Desktop/Scraping project/venv/lib/python3.7/site-packages/django/core/handlers/base.py", line 115, in _get_response
    response = self.process_exception_by_middleware(e, request)
  File "/Users/christopherencalada/Desktop/Scraping project/venv/lib/python3.7/site-packages/django/core/handlers/base.py", line 113, in _get_response
    response = wrapped_callback(request, *callback_args, **callback_kwargs)
  File "/Users/christopherencalada/Desktop/Scraping project/scrape_libgen/b_books/downloads/forms.py", line 45, in Author
    return redirect('Author',args=cd)
  File "/Users/christopherencalada/Desktop/Scraping project/venv/lib/python3.7/site-packages/django/shortcuts.py", line 58, in redirect
    return redirect_class(resolve_url(to, *args, **kwargs))
  File "/Users/christopherencalada/Desktop/Scraping project/venv/lib/python3.7/site-packages/django/shortcuts.py", line 148, in resolve_url
    return reverse(to, args=args, kwargs=kwargs)
  File "/Users/christopherencalada/Desktop/Scraping project/venv/lib/python3.7/site-packages/django/urls/base.py", line 90, in reverse
    return iri_to_uri(resolver._reverse_with_prefix(view, prefix, *args, **kwargs))
  File "/Users/christopherencalada/Desktop/Scraping project/venv/lib/python3.7/site-packages/django/urls/resolvers.py", line 668, in _reverse_with_prefix
    raise NoReverseMatch(msg)
django.urls.exceptions.NoReverseMatch: Reverse for 'Author' with keyword arguments '{'args': 'murakami'}' not found. 1 pattern(s) tried: ['Author/(?P<name>[^/]+)/$']
ERROR 2019-09-09 22:59:38,553 log 27955 123145312813056 Internal Server Error: /
Traceback (most recent call last):
  File "/Users/christopherencalada/Desktop/Scraping project/venv/lib/python3.7/site-packages/django/core/handlers/exception.py", line 34, in inner
    response = get_response(request)
  File "/Users/christopherencalada/Desktop/Scraping project/venv/lib/python3.7/site-packages/django/core/handlers/base.py", line 115, in _get_response
    response = self.process_exception_by_middleware(e, request)
  File "/Users/christopherencalada/Desktop/Scraping project/venv/lib/python3.7/site-packages/django/core/handlers/base.py", line 113, in _get_response
    response = wrapped_callback(request, *callback_args, **callback_kwargs)
  File "/Users/christopherencalada/Desktop/Scraping project/scrape_libgen/b_books/downloads/forms.py", line 45, in Author
    return redirect(reverse('Author',args=cd))
  File "/Users/christopherencalada/Desktop/Scraping project/venv/lib/python3.7/site-packages/django/urls/base.py", line 90, in reverse
    return iri_to_uri(resolver._reverse_with_prefix(view, prefix, *args, **kwargs))
  File "/Users/christopherencalada/Desktop/Scraping project/venv/lib/python3.7/site-packages/django/urls/resolvers.py", line 668, in _reverse_with_prefix
    raise NoReverseMatch(msg)
django.urls.exceptions.NoReverseMatch: Reverse for 'Author' with arguments '('m', 'u', 'r', 'a', 'k', 'a', 'm', 'i')' not found. 1 pattern(s) tried: ['Author/(?P<name>[^/]+)/$']
ERROR 2019-09-09 22:59:56,815 log 27960 123145312813056 Internal Server Error: /
Traceback (most recent call last):
  File "/Users/christopherencalada/Desktop/Scraping project/venv/lib/python3.7/site-packages/django/core/handlers/exception.py", line 34, in inner
    response = get_response(request)
  File "/Users/christopherencalada/Desktop/Scraping project/venv/lib/python3.7/site-packages/django/core/handlers/base.py", line 115, in _get_response
    response = self.process_exception_by_middleware(e, request)
  File "/Users/christopherencalada/Desktop/Scraping project/venv/lib/python3.7/site-packages/django/core/handlers/base.py", line 113, in _get_response
    response = wrapped_callback(request, *callback_args, **callback_kwargs)
  File "/Users/christopherencalada/Desktop/Scraping project/scrape_libgen/b_books/downloads/forms.py", line 45, in Author
    return redirect(reverse('Author',args=str(cd)))
  File "/Users/christopherencalada/Desktop/Scraping project/venv/lib/python3.7/site-packages/django/urls/base.py", line 90, in reverse
    return iri_to_uri(resolver._reverse_with_prefix(view, prefix, *args, **kwargs))
  File "/Users/christopherencalada/Desktop/Scraping project/venv/lib/python3.7/site-packages/django/urls/resolvers.py", line 668, in _reverse_with_prefix
    raise NoReverseMatch(msg)
django.urls.exceptions.NoReverseMatch: Reverse for 'Author' with arguments '('m', 'u', 'r', 'a', 'k', 'a', 'm', 'i')' not found. 1 pattern(s) tried: ['Author/(?P<name>[^/]+)/$']
ERROR 2019-09-09 23:00:17,741 log 27960 123145312813056 Internal Server Error: /
Traceback (most recent call last):
  File "/Users/christopherencalada/Desktop/Scraping project/venv/lib/python3.7/site-packages/django/core/handlers/exception.py", line 34, in inner
    response = get_response(request)
  File "/Users/christopherencalada/Desktop/Scraping project/venv/lib/python3.7/site-packages/django/core/handlers/base.py", line 115, in _get_response
    response = self.process_exception_by_middleware(e, request)
  File "/Users/christopherencalada/Desktop/Scraping project/venv/lib/python3.7/site-packages/django/core/handlers/base.py", line 113, in _get_response
    response = wrapped_callback(request, *callback_args, **callback_kwargs)
  File "/Users/christopherencalada/Desktop/Scraping project/scrape_libgen/b_books/downloads/forms.py", line 45, in Author
    return redirect(reverse('Author',args=str(cd)))
  File "/Users/christopherencalada/Desktop/Scraping project/venv/lib/python3.7/site-packages/django/urls/base.py", line 90, in reverse
    return iri_to_uri(resolver._reverse_with_prefix(view, prefix, *args, **kwargs))
  File "/Users/christopherencalada/Desktop/Scraping project/venv/lib/python3.7/site-packages/django/urls/resolvers.py", line 668, in _reverse_with_prefix
    raise NoReverseMatch(msg)
django.urls.exceptions.NoReverseMatch: Reverse for 'Author' with arguments '('m', 'u', 'r', 'a', 'k', 'a', 'm', 'i')' not found. 1 pattern(s) tried: ['Author/(?P<name>[^/]+)/$']
ERROR 2019-09-09 23:03:50,901 log 27984 123145312813056 Internal Server Error: /
Traceback (most recent call last):
  File "/Users/christopherencalada/Desktop/Scraping project/venv/lib/python3.7/site-packages/django/forms/forms.py", line 163, in __getitem__
    field = self.fields[name]
KeyError: 'A_name'

During handling of the above exception, another exception occurred:

Traceback (most recent call last):
  File "/Users/christopherencalada/Desktop/Scraping project/venv/lib/python3.7/site-packages/django/core/handlers/exception.py", line 34, in inner
    response = get_response(request)
  File "/Users/christopherencalada/Desktop/Scraping project/venv/lib/python3.7/site-packages/django/core/handlers/base.py", line 115, in _get_response
    response = self.process_exception_by_middleware(e, request)
  File "/Users/christopherencalada/Desktop/Scraping project/venv/lib/python3.7/site-packages/django/core/handlers/base.py", line 113, in _get_response
    response = wrapped_callback(request, *callback_args, **callback_kwargs)
  File "/Users/christopherencalada/Desktop/Scraping project/scrape_libgen/b_books/downloads/forms.py", line 45, in Author
    return redirect(reverse('Author',args=form['A_name'].value()))
  File "/Users/christopherencalada/Desktop/Scraping project/venv/lib/python3.7/site-packages/django/forms/forms.py", line 169, in __getitem__
    ', '.join(sorted(f for f in self.fields)),
KeyError: "Key 'A_name' not found in 'AuthorForm'. Choices are: A_Name."
ERROR 2019-09-09 23:04:00,317 log 27987 123145312813056 Internal Server Error: /
Traceback (most recent call last):
  File "/Users/christopherencalada/Desktop/Scraping project/venv/lib/python3.7/site-packages/django/core/handlers/exception.py", line 34, in inner
    response = get_response(request)
  File "/Users/christopherencalada/Desktop/Scraping project/venv/lib/python3.7/site-packages/django/core/handlers/base.py", line 115, in _get_response
    response = self.process_exception_by_middleware(e, request)
  File "/Users/christopherencalada/Desktop/Scraping project/venv/lib/python3.7/site-packages/django/core/handlers/base.py", line 113, in _get_response
    response = wrapped_callback(request, *callback_args, **callback_kwargs)
  File "/Users/christopherencalada/Desktop/Scraping project/scrape_libgen/b_books/downloads/forms.py", line 45, in Author
    return redirect(reverse('Author',args=form['A_Name'].value()))
  File "/Users/christopherencalada/Desktop/Scraping project/venv/lib/python3.7/site-packages/django/urls/base.py", line 90, in reverse
    return iri_to_uri(resolver._reverse_with_prefix(view, prefix, *args, **kwargs))
  File "/Users/christopherencalada/Desktop/Scraping project/venv/lib/python3.7/site-packages/django/urls/resolvers.py", line 668, in _reverse_with_prefix
    raise NoReverseMatch(msg)
django.urls.exceptions.NoReverseMatch: Reverse for 'Author' with arguments '('m', 'u', 'r', 'a', 'k', 'a', 'm', 'i')' not found. 1 pattern(s) tried: ['Author/(?P<name>[^/]+)/$']
ERROR 2019-09-09 23:04:11,033 log 27989 123145312813056 Internal Server Error: /Author/<input type="text" name="A_Name" value="murakami" maxlength="100" id="id_A_Name" required>/
Traceback (most recent call last):
  File "/Users/christopherencalada/Desktop/Scraping project/venv/lib/python3.7/site-packages/django/core/handlers/exception.py", line 34, in inner
    response = get_response(request)
  File "/Users/christopherencalada/Desktop/Scraping project/venv/lib/python3.7/site-packages/django/core/handlers/base.py", line 115, in _get_response
    response = self.process_exception_by_middleware(e, request)
  File "/Users/christopherencalada/Desktop/Scraping project/venv/lib/python3.7/site-packages/django/core/handlers/base.py", line 113, in _get_response
    response = wrapped_callback(request, *callback_args, **callback_kwargs)
  File "/Users/christopherencalada/Desktop/Scraping project/scrape_libgen/b_books/downloads/views.py", line 15, in Author_redirect
    return render(request,'downloads/index.html',name)
  File "/Users/christopherencalada/Desktop/Scraping project/venv/lib/python3.7/site-packages/django/shortcuts.py", line 36, in render
    content = loader.render_to_string(template_name, context, request, using=using)
  File "/Users/christopherencalada/Desktop/Scraping project/venv/lib/python3.7/site-packages/django/template/loader.py", line 62, in render_to_string
    return template.render(context, request)
  File "/Users/christopherencalada/Desktop/Scraping project/venv/lib/python3.7/site-packages/django/template/backends/django.py", line 59, in render
    context = make_context(context, request, autoescape=self.backend.engine.autoescape)
  File "/Users/christopherencalada/Desktop/Scraping project/venv/lib/python3.7/site-packages/django/template/context.py", line 270, in make_context
    raise TypeError('context must be a dict rather than %s.' % context.__class__.__name__)
TypeError: context must be a dict rather than str.
ERROR 2019-09-09 23:07:11,910 log 28005 123145312813056 Internal Server Error: /
Traceback (most recent call last):
  File "/Users/christopherencalada/Desktop/Scraping project/venv/lib/python3.7/site-packages/django/core/handlers/exception.py", line 34, in inner
    response = get_response(request)
  File "/Users/christopherencalada/Desktop/Scraping project/venv/lib/python3.7/site-packages/django/core/handlers/base.py", line 115, in _get_response
    response = self.process_exception_by_middleware(e, request)
  File "/Users/christopherencalada/Desktop/Scraping project/venv/lib/python3.7/site-packages/django/core/handlers/base.py", line 113, in _get_response
    response = wrapped_callback(request, *callback_args, **callback_kwargs)
  File "/Users/christopherencalada/Desktop/Scraping project/scrape_libgen/b_books/downloads/forms.py", line 45, in Author
    return redirect(reverse('Author',args=name))
  File "/Users/christopherencalada/Desktop/Scraping project/venv/lib/python3.7/site-packages/django/urls/base.py", line 90, in reverse
    return iri_to_uri(resolver._reverse_with_prefix(view, prefix, *args, **kwargs))
  File "/Users/christopherencalada/Desktop/Scraping project/venv/lib/python3.7/site-packages/django/urls/resolvers.py", line 668, in _reverse_with_prefix
    raise NoReverseMatch(msg)
django.urls.exceptions.NoReverseMatch: Reverse for 'Author' with arguments '('m', 'u', 'r', 'a', 'k', 'a', 'm', 'i')' not found. 1 pattern(s) tried: ['Author/(?P<name>[^/]+)/$']
ERROR 2019-09-09 23:31:59,082 log 28100 123145312813056 Internal Server Error: /Author/murakami/
Traceback (most recent call last):
  File "/Users/christopherencalada/Desktop/Scraping project/venv/lib/python3.7/site-packages/django/core/handlers/exception.py", line 34, in inner
    response = get_response(request)
  File "/Users/christopherencalada/Desktop/Scraping project/venv/lib/python3.7/site-packages/django/core/handlers/base.py", line 115, in _get_response
    response = self.process_exception_by_middleware(e, request)
  File "/Users/christopherencalada/Desktop/Scraping project/venv/lib/python3.7/site-packages/django/core/handlers/base.py", line 113, in _get_response
    response = wrapped_callback(request, *callback_args, **callback_kwargs)
TypeError: Author_redirect() got an unexpected keyword argument 'name'
ERROR 2019-09-09 23:32:39,861 log 28105 123145312813056 Internal Server Error: /Author/murakami/
Traceback (most recent call last):
  File "/Users/christopherencalada/Desktop/Scraping project/venv/lib/python3.7/site-packages/django/core/handlers/exception.py", line 34, in inner
    response = get_response(request)
  File "/Users/christopherencalada/Desktop/Scraping project/venv/lib/python3.7/site-packages/django/core/handlers/base.py", line 115, in _get_response
    response = self.process_exception_by_middleware(e, request)
  File "/Users/christopherencalada/Desktop/Scraping project/venv/lib/python3.7/site-packages/django/core/handlers/base.py", line 113, in _get_response
    response = wrapped_callback(request, *callback_args, **callback_kwargs)
TypeError: Author_redirect() got an unexpected keyword argument 'name'
ERROR 2019-09-09 23:33:04,361 log 28114 123145312813056 Internal Server Error: /Author/murakami/
Traceback (most recent call last):
  File "/Users/christopherencalada/Desktop/Scraping project/venv/lib/python3.7/site-packages/django/core/handlers/exception.py", line 34, in inner
    response = get_response(request)
  File "/Users/christopherencalada/Desktop/Scraping project/venv/lib/python3.7/site-packages/django/core/handlers/base.py", line 115, in _get_response
    response = self.process_exception_by_middleware(e, request)
  File "/Users/christopherencalada/Desktop/Scraping project/venv/lib/python3.7/site-packages/django/core/handlers/base.py", line 113, in _get_response
    response = wrapped_callback(request, *callback_args, **callback_kwargs)
TypeError: Author_redirect() missing 1 required positional argument: 'cd'
ERROR 2019-09-09 23:33:21,320 log 28118 123145312813056 Internal Server Error: /Author/murakami/
Traceback (most recent call last):
  File "/Users/christopherencalada/Desktop/Scraping project/venv/lib/python3.7/site-packages/django/core/handlers/exception.py", line 34, in inner
    response = get_response(request)
  File "/Users/christopherencalada/Desktop/Scraping project/venv/lib/python3.7/site-packages/django/core/handlers/base.py", line 115, in _get_response
    response = self.process_exception_by_middleware(e, request)
  File "/Users/christopherencalada/Desktop/Scraping project/venv/lib/python3.7/site-packages/django/core/handlers/base.py", line 113, in _get_response
    response = wrapped_callback(request, *callback_args, **callback_kwargs)
TypeError: Author_redirect() missing 1 required positional argument: 'cd'
ERROR 2019-09-09 23:34:06,223 log 28130 123145312813056 Internal Server Error: /Author/murakami/
Traceback (most recent call last):
  File "/Users/christopherencalada/Desktop/Scraping project/venv/lib/python3.7/site-packages/django/core/handlers/exception.py", line 34, in inner
    response = get_response(request)
  File "/Users/christopherencalada/Desktop/Scraping project/venv/lib/python3.7/site-packages/django/core/handlers/base.py", line 115, in _get_response
    response = self.process_exception_by_middleware(e, request)
  File "/Users/christopherencalada/Desktop/Scraping project/venv/lib/python3.7/site-packages/django/core/handlers/base.py", line 113, in _get_response
    response = wrapped_callback(request, *callback_args, **callback_kwargs)
TypeError: Author_redirect() missing 1 required positional argument: 'cd'
ERROR 2019-09-09 23:55:09,881 log 28179 123145312813056 Internal Server Error: /Author/murakami/
Traceback (most recent call last):
  File "/Users/christopherencalada/Desktop/Scraping project/venv/lib/python3.7/site-packages/django/core/handlers/exception.py", line 34, in inner
    response = get_response(request)
  File "/Users/christopherencalada/Desktop/Scraping project/venv/lib/python3.7/site-packages/django/core/handlers/base.py", line 115, in _get_response
    response = self.process_exception_by_middleware(e, request)
  File "/Users/christopherencalada/Desktop/Scraping project/venv/lib/python3.7/site-packages/django/core/handlers/base.py", line 113, in _get_response
    response = wrapped_callback(request, *callback_args, **callback_kwargs)
  File "/Users/christopherencalada/Desktop/Scraping project/scrape_libgen/b_books/downloads/views.py", line 15, in Author_redirect
    return render(request,'downloads/index.html',{'name':Books.objects.values('Author').filter(Author__contains=name).distinct().annotate(Title_count=Count('Title'))})
NameError: name 'Count' is not defined
ERROR 2019-09-10 02:05:19,283 log 28371 123145312813056 Internal Server Error: /Author/haruki murakami/
Traceback (most recent call last):
  File "/Users/christopherencalada/Desktop/Scraping project/venv/lib/python3.7/site-packages/django/core/handlers/exception.py", line 34, in inner
    response = get_response(request)
  File "/Users/christopherencalada/Desktop/Scraping project/venv/lib/python3.7/site-packages/django/core/handlers/base.py", line 115, in _get_response
    response = self.process_exception_by_middleware(e, request)
  File "/Users/christopherencalada/Desktop/Scraping project/venv/lib/python3.7/site-packages/django/core/handlers/base.py", line 113, in _get_response
    response = wrapped_callback(request, *callback_args, **callback_kwargs)
  File "/Users/christopherencalada/Desktop/Scraping project/scrape_libgen/b_books/downloads/views.py", line 18, in Author_redirect
    return render(request,'downloads/index.html',{'name':Books.objects.values('Author').filter(Author__contains=name).distinct().annotate(Title_count=Count('Title'))})
  File "/Users/christopherencalada/Desktop/Scraping project/venv/lib/python3.7/site-packages/django/shortcuts.py", line 36, in render
    content = loader.render_to_string(template_name, context, request, using=using)
  File "/Users/christopherencalada/Desktop/Scraping project/venv/lib/python3.7/site-packages/django/template/loader.py", line 62, in render_to_string
    return template.render(context, request)
  File "/Users/christopherencalada/Desktop/Scraping project/venv/lib/python3.7/site-packages/django/template/backends/django.py", line 61, in render
    return self.template.render(context)
  File "/Users/christopherencalada/Desktop/Scraping project/venv/lib/python3.7/site-packages/django/template/base.py", line 171, in render
    return self._render(context)
  File "/Users/christopherencalada/Desktop/Scraping project/venv/lib/python3.7/site-packages/django/template/base.py", line 163, in _render
    return self.nodelist.render(context)
  File "/Users/christopherencalada/Desktop/Scraping project/venv/lib/python3.7/site-packages/django/template/base.py", line 937, in render
    bit = node.render_annotated(context)
  File "/Users/christopherencalada/Desktop/Scraping project/venv/lib/python3.7/site-packages/django/template/base.py", line 904, in render_annotated
    return self.render(context)
  File "/Users/christopherencalada/Desktop/Scraping project/venv/lib/python3.7/site-packages/django/template/defaulttags.py", line 443, in render
    url = reverse(view_name, args=args, kwargs=kwargs, current_app=current_app)
  File "/Users/christopherencalada/Desktop/Scraping project/venv/lib/python3.7/site-packages/django/urls/base.py", line 90, in reverse
    return iri_to_uri(resolver._reverse_with_prefix(view, prefix, *args, **kwargs))
  File "/Users/christopherencalada/Desktop/Scraping project/venv/lib/python3.7/site-packages/django/urls/resolvers.py", line 668, in _reverse_with_prefix
    raise NoReverseMatch(msg)
django.urls.exceptions.NoReverseMatch: Reverse for 'books' with no arguments not found. 1 pattern(s) tried: ['Author/(?P<name>[^/]+)/books$']
ERROR 2019-09-10 21:05:40,017 log 28922 123145312813056 Internal Server Error: /Author/haruki murakami/
Traceback (most recent call last):
  File "/Users/christopherencalada/Desktop/Scraping project/venv/lib/python3.7/site-packages/django/core/handlers/exception.py", line 34, in inner
    response = get_response(request)
  File "/Users/christopherencalada/Desktop/Scraping project/venv/lib/python3.7/site-packages/django/core/handlers/base.py", line 115, in _get_response
    response = self.process_exception_by_middleware(e, request)
  File "/Users/christopherencalada/Desktop/Scraping project/venv/lib/python3.7/site-packages/django/core/handlers/base.py", line 113, in _get_response
    response = wrapped_callback(request, *callback_args, **callback_kwargs)
  File "/Users/christopherencalada/Desktop/Scraping project/scrape_libgen/b_books/downloads/views.py", line 20, in Author_redirect
    return render(request,'downloads/index.html',{'name':Books.objects.values('Author').filter(Author__contains=name).distinct().annotate(Title_count=Count('Title'))})
  File "/Users/christopherencalada/Desktop/Scraping project/venv/lib/python3.7/site-packages/django/shortcuts.py", line 36, in render
    content = loader.render_to_string(template_name, context, request, using=using)
  File "/Users/christopherencalada/Desktop/Scraping project/venv/lib/python3.7/site-packages/django/template/loader.py", line 62, in render_to_string
    return template.render(context, request)
  File "/Users/christopherencalada/Desktop/Scraping project/venv/lib/python3.7/site-packages/django/template/backends/django.py", line 61, in render
    return self.template.render(context)
  File "/Users/christopherencalada/Desktop/Scraping project/venv/lib/python3.7/site-packages/django/template/base.py", line 171, in render
    return self._render(context)
  File "/Users/christopherencalada/Desktop/Scraping project/venv/lib/python3.7/site-packages/django/template/base.py", line 163, in _render
    return self.nodelist.render(context)
  File "/Users/christopherencalada/Desktop/Scraping project/venv/lib/python3.7/site-packages/django/template/base.py", line 937, in render
    bit = node.render_annotated(context)
  File "/Users/christopherencalada/Desktop/Scraping project/venv/lib/python3.7/site-packages/django/template/base.py", line 904, in render_annotated
    return self.render(context)
  File "/Users/christopherencalada/Desktop/Scraping project/venv/lib/python3.7/site-packages/django/template/defaulttags.py", line 443, in render
    url = reverse(view_name, args=args, kwargs=kwargs, current_app=current_app)
  File "/Users/christopherencalada/Desktop/Scraping project/venv/lib/python3.7/site-packages/django/urls/base.py", line 90, in reverse
    return iri_to_uri(resolver._reverse_with_prefix(view, prefix, *args, **kwargs))
  File "/Users/christopherencalada/Desktop/Scraping project/venv/lib/python3.7/site-packages/django/urls/resolvers.py", line 668, in _reverse_with_prefix
    raise NoReverseMatch(msg)
django.urls.exceptions.NoReverseMatch: Reverse for 'books' with no arguments not found. 1 pattern(s) tried: ['Author/(?P<name>[^/]+)/books$']
ERROR 2019-09-10 21:06:06,546 log 28922 123145312813056 Internal Server Error: /Author/haruki murakami/
Traceback (most recent call last):
  File "/Users/christopherencalada/Desktop/Scraping project/venv/lib/python3.7/site-packages/django/core/handlers/exception.py", line 34, in inner
    response = get_response(request)
  File "/Users/christopherencalada/Desktop/Scraping project/venv/lib/python3.7/site-packages/django/core/handlers/base.py", line 115, in _get_response
    response = self.process_exception_by_middleware(e, request)
  File "/Users/christopherencalada/Desktop/Scraping project/venv/lib/python3.7/site-packages/django/core/handlers/base.py", line 113, in _get_response
    response = wrapped_callback(request, *callback_args, **callback_kwargs)
  File "/Users/christopherencalada/Desktop/Scraping project/scrape_libgen/b_books/downloads/views.py", line 20, in Author_redirect
    return render(request,'downloads/index.html',{'name':Books.objects.values('Author').filter(Author__contains=name).distinct().annotate(Title_count=Count('Title'))})
  File "/Users/christopherencalada/Desktop/Scraping project/venv/lib/python3.7/site-packages/django/shortcuts.py", line 36, in render
    content = loader.render_to_string(template_name, context, request, using=using)
  File "/Users/christopherencalada/Desktop/Scraping project/venv/lib/python3.7/site-packages/django/template/loader.py", line 62, in render_to_string
    return template.render(context, request)
  File "/Users/christopherencalada/Desktop/Scraping project/venv/lib/python3.7/site-packages/django/template/backends/django.py", line 61, in render
    return self.template.render(context)
  File "/Users/christopherencalada/Desktop/Scraping project/venv/lib/python3.7/site-packages/django/template/base.py", line 171, in render
    return self._render(context)
  File "/Users/christopherencalada/Desktop/Scraping project/venv/lib/python3.7/site-packages/django/template/base.py", line 163, in _render
    return self.nodelist.render(context)
  File "/Users/christopherencalada/Desktop/Scraping project/venv/lib/python3.7/site-packages/django/template/base.py", line 937, in render
    bit = node.render_annotated(context)
  File "/Users/christopherencalada/Desktop/Scraping project/venv/lib/python3.7/site-packages/django/template/base.py", line 904, in render_annotated
    return self.render(context)
  File "/Users/christopherencalada/Desktop/Scraping project/venv/lib/python3.7/site-packages/django/template/defaulttags.py", line 443, in render
    url = reverse(view_name, args=args, kwargs=kwargs, current_app=current_app)
  File "/Users/christopherencalada/Desktop/Scraping project/venv/lib/python3.7/site-packages/django/urls/base.py", line 90, in reverse
    return iri_to_uri(resolver._reverse_with_prefix(view, prefix, *args, **kwargs))
  File "/Users/christopherencalada/Desktop/Scraping project/venv/lib/python3.7/site-packages/django/urls/resolvers.py", line 668, in _reverse_with_prefix
    raise NoReverseMatch(msg)
django.urls.exceptions.NoReverseMatch: Reverse for 'books' with no arguments not found. 1 pattern(s) tried: ['Author/(?P<name>[^/]+)/books$']
ERROR 2019-09-10 21:06:44,861 log 28930 123145312813056 Internal Server Error: /Author/haruki murakami/
Traceback (most recent call last):
  File "/Users/christopherencalada/Desktop/Scraping project/venv/lib/python3.7/site-packages/django/core/handlers/exception.py", line 34, in inner
    response = get_response(request)
  File "/Users/christopherencalada/Desktop/Scraping project/venv/lib/python3.7/site-packages/django/core/handlers/base.py", line 115, in _get_response
    response = self.process_exception_by_middleware(e, request)
  File "/Users/christopherencalada/Desktop/Scraping project/venv/lib/python3.7/site-packages/django/core/handlers/base.py", line 113, in _get_response
    response = wrapped_callback(request, *callback_args, **callback_kwargs)
  File "/Users/christopherencalada/Desktop/Scraping project/scrape_libgen/b_books/downloads/views.py", line 20, in Author_redirect
    return render(request,'downloads/index.html',{'name':Books.objects.values('Author').filter(Author__contains=name).distinct().annotate(Title_count=Count('Title'))})
  File "/Users/christopherencalada/Desktop/Scraping project/venv/lib/python3.7/site-packages/django/shortcuts.py", line 36, in render
    content = loader.render_to_string(template_name, context, request, using=using)
  File "/Users/christopherencalada/Desktop/Scraping project/venv/lib/python3.7/site-packages/django/template/loader.py", line 62, in render_to_string
    return template.render(context, request)
  File "/Users/christopherencalada/Desktop/Scraping project/venv/lib/python3.7/site-packages/django/template/backends/django.py", line 61, in render
    return self.template.render(context)
  File "/Users/christopherencalada/Desktop/Scraping project/venv/lib/python3.7/site-packages/django/template/base.py", line 171, in render
    return self._render(context)
  File "/Users/christopherencalada/Desktop/Scraping project/venv/lib/python3.7/site-packages/django/template/base.py", line 163, in _render
    return self.nodelist.render(context)
  File "/Users/christopherencalada/Desktop/Scraping project/venv/lib/python3.7/site-packages/django/template/base.py", line 937, in render
    bit = node.render_annotated(context)
  File "/Users/christopherencalada/Desktop/Scraping project/venv/lib/python3.7/site-packages/django/template/base.py", line 904, in render_annotated
    return self.render(context)
  File "/Users/christopherencalada/Desktop/Scraping project/venv/lib/python3.7/site-packages/django/template/defaulttags.py", line 443, in render
    url = reverse(view_name, args=args, kwargs=kwargs, current_app=current_app)
  File "/Users/christopherencalada/Desktop/Scraping project/venv/lib/python3.7/site-packages/django/urls/base.py", line 90, in reverse
    return iri_to_uri(resolver._reverse_with_prefix(view, prefix, *args, **kwargs))
  File "/Users/christopherencalada/Desktop/Scraping project/venv/lib/python3.7/site-packages/django/urls/resolvers.py", line 668, in _reverse_with_prefix
    raise NoReverseMatch(msg)
django.urls.exceptions.NoReverseMatch: Reverse for 'books' not found. 'books' is not a valid view function or pattern name.
ERROR 2019-09-10 21:07:35,970 log 28938 123145312813056 Internal Server Error: /Author/haruki murakami/
Traceback (most recent call last):
  File "/Users/christopherencalada/Desktop/Scraping project/venv/lib/python3.7/site-packages/django/core/handlers/exception.py", line 34, in inner
    response = get_response(request)
  File "/Users/christopherencalada/Desktop/Scraping project/venv/lib/python3.7/site-packages/django/core/handlers/base.py", line 115, in _get_response
    response = self.process_exception_by_middleware(e, request)
  File "/Users/christopherencalada/Desktop/Scraping project/venv/lib/python3.7/site-packages/django/core/handlers/base.py", line 113, in _get_response
    response = wrapped_callback(request, *callback_args, **callback_kwargs)
  File "/Users/christopherencalada/Desktop/Scraping project/scrape_libgen/b_books/downloads/views.py", line 18, in Author_redirect
    print(x[1])
IndexError: list index out of range
ERROR 2019-09-10 21:07:44,075 log 28940 123145312813056 Internal Server Error: /Author/haruki murakami/
Traceback (most recent call last):
  File "/Users/christopherencalada/Desktop/Scraping project/venv/lib/python3.7/site-packages/django/core/handlers/exception.py", line 34, in inner
    response = get_response(request)
  File "/Users/christopherencalada/Desktop/Scraping project/venv/lib/python3.7/site-packages/django/core/handlers/base.py", line 115, in _get_response
    response = self.process_exception_by_middleware(e, request)
  File "/Users/christopherencalada/Desktop/Scraping project/venv/lib/python3.7/site-packages/django/core/handlers/base.py", line 113, in _get_response
    response = wrapped_callback(request, *callback_args, **callback_kwargs)
  File "/Users/christopherencalada/Desktop/Scraping project/scrape_libgen/b_books/downloads/views.py", line 18, in Author_redirect
    print(x[0])
IndexError: list index out of range
ERROR 2019-09-10 21:08:08,043 log 28940 123145312813056 Internal Server Error: /Author/haruki murakami/
Traceback (most recent call last):
  File "/Users/christopherencalada/Desktop/Scraping project/venv/lib/python3.7/site-packages/django/core/handlers/exception.py", line 34, in inner
    response = get_response(request)
  File "/Users/christopherencalada/Desktop/Scraping project/venv/lib/python3.7/site-packages/django/core/handlers/base.py", line 115, in _get_response
    response = self.process_exception_by_middleware(e, request)
  File "/Users/christopherencalada/Desktop/Scraping project/venv/lib/python3.7/site-packages/django/core/handlers/base.py", line 113, in _get_response
    response = wrapped_callback(request, *callback_args, **callback_kwargs)
  File "/Users/christopherencalada/Desktop/Scraping project/scrape_libgen/b_books/downloads/views.py", line 18, in Author_redirect
    print(x[0])
IndexError: list index out of range
ERROR 2019-09-11 21:22:29,178 log 29268 123145312813056 Internal Server Error: /Author/haruki murakami/
Traceback (most recent call last):
  File "/Users/christopherencalada/Desktop/Scraping project/venv/lib/python3.7/site-packages/django/core/handlers/exception.py", line 34, in inner
    response = get_response(request)
  File "/Users/christopherencalada/Desktop/Scraping project/venv/lib/python3.7/site-packages/django/core/handlers/base.py", line 115, in _get_response
    response = self.process_exception_by_middleware(e, request)
  File "/Users/christopherencalada/Desktop/Scraping project/venv/lib/python3.7/site-packages/django/core/handlers/base.py", line 113, in _get_response
    response = wrapped_callback(request, *callback_args, **callback_kwargs)
  File "/Users/christopherencalada/Desktop/Scraping project/scrape_libgen/b_books/downloads/views.py", line 18, in Author_redirect
    form = AuthorForm(request.post)
AttributeError: 'WSGIRequest' object has no attribute 'post'
ERROR 2019-09-11 21:23:18,195 log 29273 123145312813056 Internal Server Error: /Author/haruki murakami/
Traceback (most recent call last):
  File "/Users/christopherencalada/Desktop/Scraping project/venv/lib/python3.7/site-packages/django/core/handlers/exception.py", line 34, in inner
    response = get_response(request)
  File "/Users/christopherencalada/Desktop/Scraping project/venv/lib/python3.7/site-packages/django/core/handlers/base.py", line 115, in _get_response
    response = self.process_exception_by_middleware(e, request)
  File "/Users/christopherencalada/Desktop/Scraping project/venv/lib/python3.7/site-packages/django/core/handlers/base.py", line 113, in _get_response
    response = wrapped_callback(request, *callback_args, **callback_kwargs)
  File "/Users/christopherencalada/Desktop/Scraping project/scrape_libgen/b_books/downloads/views.py", line 21, in Author_redirect
    print(x)
UnboundLocalError: local variable 'x' referenced before assignment
ERROR 2019-09-11 21:34:30,138 log 29312 123145312813056 Internal Server Error: /Author/haruki murakami/
Traceback (most recent call last):
  File "/Users/christopherencalada/Desktop/Scraping project/venv/lib/python3.7/site-packages/django/core/handlers/exception.py", line 34, in inner
    response = get_response(request)
  File "/Users/christopherencalada/Desktop/Scraping project/venv/lib/python3.7/site-packages/django/core/handlers/base.py", line 126, in _get_response
    "returned None instead." % (callback.__module__, view_name)
ValueError: The view downloads.views.Author_redirect didn't return an HttpResponse object. It returned None instead.
ERROR 2019-09-12 04:21:49,937 log 29689 123145312813056 Internal Server Error: /Author/haruki murakami/
Traceback (most recent call last):
  File "/Users/christopherencalada/Desktop/Scraping project/venv/lib/python3.7/site-packages/django/forms/forms.py", line 163, in __getitem__
    field = self.fields[name]
KeyError: 'get_book'

During handling of the above exception, another exception occurred:

Traceback (most recent call last):
  File "/Users/christopherencalada/Desktop/Scraping project/venv/lib/python3.7/site-packages/django/core/handlers/exception.py", line 34, in inner
    response = get_response(request)
  File "/Users/christopherencalada/Desktop/Scraping project/venv/lib/python3.7/site-packages/django/core/handlers/base.py", line 115, in _get_response
    response = self.process_exception_by_middleware(e, request)
  File "/Users/christopherencalada/Desktop/Scraping project/venv/lib/python3.7/site-packages/django/core/handlers/base.py", line 113, in _get_response
    response = wrapped_callback(request, *callback_args, **callback_kwargs)
  File "/Users/christopherencalada/Desktop/Scraping project/scrape_libgen/b_books/downloads/views.py", line 22, in Author_redirect
    print(form['get_book'].value())
  File "/Users/christopherencalada/Desktop/Scraping project/venv/lib/python3.7/site-packages/django/forms/forms.py", line 169, in __getitem__
    ', '.join(sorted(f for f in self.fields)),
KeyError: "Key 'get_book' not found in 'AuthorForm'. Choices are: A_Name."
ERROR 2019-09-12 20:50:08,207 log 699 123145312813056 Internal Server Error: /Author/haruki murakami/
Traceback (most recent call last):
  File "/Users/christopherencalada/Desktop/Scraping project/venv/lib/python3.7/site-packages/django/core/handlers/exception.py", line 34, in inner
    response = get_response(request)
  File "/Users/christopherencalada/Desktop/Scraping project/venv/lib/python3.7/site-packages/django/core/handlers/base.py", line 115, in _get_response
    response = self.process_exception_by_middleware(e, request)
  File "/Users/christopherencalada/Desktop/Scraping project/venv/lib/python3.7/site-packages/django/core/handlers/base.py", line 113, in _get_response
    response = wrapped_callback(request, *callback_args, **callback_kwargs)
  File "/Users/christopherencalada/Desktop/Scraping project/scrape_libgen/b_books/downloads/views.py", line 21, in Author_redirect
    return redirect(reverse('books',args=selected_author))
NameError: name 'reverse' is not defined
ERROR 2019-09-12 20:50:25,630 log 702 123145312813056 Internal Server Error: /Author/haruki murakami/
Traceback (most recent call last):
  File "/Users/christopherencalada/Desktop/Scraping project/venv/lib/python3.7/site-packages/django/core/handlers/exception.py", line 34, in inner
    response = get_response(request)
  File "/Users/christopherencalada/Desktop/Scraping project/venv/lib/python3.7/site-packages/django/core/handlers/base.py", line 115, in _get_response
    response = self.process_exception_by_middleware(e, request)
  File "/Users/christopherencalada/Desktop/Scraping project/venv/lib/python3.7/site-packages/django/core/handlers/base.py", line 113, in _get_response
    response = wrapped_callback(request, *callback_args, **callback_kwargs)
  File "/Users/christopherencalada/Desktop/Scraping project/scrape_libgen/b_books/downloads/views.py", line 22, in Author_redirect
    return redirect(reverse('books',args=selected_author))
  File "/Users/christopherencalada/Desktop/Scraping project/venv/lib/python3.7/site-packages/django/urls/base.py", line 90, in reverse
    return iri_to_uri(resolver._reverse_with_prefix(view, prefix, *args, **kwargs))
  File "/Users/christopherencalada/Desktop/Scraping project/venv/lib/python3.7/site-packages/django/urls/resolvers.py", line 668, in _reverse_with_prefix
    raise NoReverseMatch(msg)
django.urls.exceptions.NoReverseMatch: Reverse for 'books' with arguments '('H', 'a', 'r', 'u', 'k', 'i', ' ', 'M', 'u', 'r', 'a', 'k', 'a', 'm', 'i')' not found. 1 pattern(s) tried: ['Author/(?P<name>[^/]+)/books$']
ERROR 2019-09-12 20:51:00,690 log 707 123145312813056 Internal Server Error: /Author/Haruki Murakami/books
Traceback (most recent call last):
  File "/Users/christopherencalada/Desktop/Scraping project/venv/lib/python3.7/site-packages/django/core/handlers/exception.py", line 34, in inner
    response = get_response(request)
  File "/Users/christopherencalada/Desktop/Scraping project/venv/lib/python3.7/site-packages/django/core/handlers/base.py", line 115, in _get_response
    response = self.process_exception_by_middleware(e, request)
  File "/Users/christopherencalada/Desktop/Scraping project/venv/lib/python3.7/site-packages/django/core/handlers/base.py", line 113, in _get_response
    response = wrapped_callback(request, *callback_args, **callback_kwargs)
  File "/Users/christopherencalada/Desktop/Scraping project/scrape_libgen/b_books/downloads/views.py", line 29, in books_redirect
    return render(request, 'downloads/book_detail.html',{'name':Books.objects.values('Title').filter(Author__contains=selected_author).distinct()})
NameError: name 'selected_author' is not defined
ERROR 2019-09-12 20:51:29,036 log 712 123145312813056 Internal Server Error: /Author/Haruki Murakami/books
Traceback (most recent call last):
  File "/Users/christopherencalada/Desktop/Scraping project/venv/lib/python3.7/site-packages/django/core/handlers/exception.py", line 34, in inner
    response = get_response(request)
  File "/Users/christopherencalada/Desktop/Scraping project/venv/lib/python3.7/site-packages/django/core/handlers/base.py", line 115, in _get_response
    response = self.process_exception_by_middleware(e, request)
  File "/Users/christopherencalada/Desktop/Scraping project/venv/lib/python3.7/site-packages/django/core/handlers/base.py", line 113, in _get_response
    response = wrapped_callback(request, *callback_args, **callback_kwargs)
TypeError: books_redirect() got an unexpected keyword argument 'name'
ERROR 2019-09-12 20:52:06,470 log 718 123145312813056 Internal Server Error: /Author/Haruki Murakami/books
Traceback (most recent call last):
  File "/Users/christopherencalada/Desktop/Scraping project/venv/lib/python3.7/site-packages/django/core/handlers/exception.py", line 34, in inner
    response = get_response(request)
  File "/Users/christopherencalada/Desktop/Scraping project/venv/lib/python3.7/site-packages/django/core/handlers/base.py", line 115, in _get_response
    response = self.process_exception_by_middleware(e, request)
  File "/Users/christopherencalada/Desktop/Scraping project/venv/lib/python3.7/site-packages/django/core/handlers/base.py", line 113, in _get_response
    response = wrapped_callback(request, *callback_args, **callback_kwargs)
TypeError: books_redirect() got an unexpected keyword argument 'name'
